Workbook

Sheet Order Details Aug22-Mar23
B3: NBF | E3: ORDER DETAILS AS PER INDENT OF NARAENDRA BREEDING FARMS | S3: Update as on 30.03.2023
B5: INDENT | D5: NARAENDRA BREEDING FARMS | F5: D E T A I L S A B O U T I T E M | K5: D E T A I L S A B O U T P R I C E | P5: D E T A I L S A B O U T P U R C H A S E O R D E R
B7: DATE OF INDENT | D7: NAME OF ITEM | F7: REQUIRE QTY | G7: UOM | H7: PACK SIZE | I7: OREDR QTY | K7: PRICE | L7: GST % | M7: GST Crgs | N7: NET PRICE | P7: PO RAISED ON | R7: PO DATE / NO | T7: NAME OF SUPPLIER
A9: 1 | B9: N A | D9: FLYVIN | F9: 70 | G9: Kg | H9: 1 | I9: =F9*H9 -> 70 | K9: 720 | M9: =K9*L9 -> 0 | N9: =K9+M9 -> 720 | P9: 44803 | R9: PO / NBF / 300822/ 01 | T9: We Care Animal Health
A10: 2 | B10: 44803 | D10: DLM | F10: 20 | G10: Kg | H10: 25 | I10: =F10*H10 -> 500 | M10: =K10*L10 -> 0 | N10: =K10+M10 -> 0 | R10: PO / NBF / | T10: Supplied from Hitech Kolkata
A11: 3 | B11: 44803 | D11: BREEDER VITAMIN PREMIX-HYD | F11: 20 | G11: Kg | H11: 25 | I11: =F11*H11 -> 500 | K11: 18100 | M11: =K11*L11 -> 0 | N11: =K11+M11 -> 18100 | P11: 44810 | R11: PO / NBF / 060922 / 01 | T11: Avitech Nutrition Pvt Ltd
A12: 4 | B12: 44809 | D12: ALKAKARB (Sodi Bicarb) | F12: 30 | G12: Kg | H12: 50 | I12: =F12*H12 -> 1500 | M12: =K12*L12 -> 0 | N12: =K12+M12 -> 0 | R12: PO / NBF / | T12: Supplied from Hitech Kolkata
A13: 5 | B13: 44809 | D13: KEMZYME - XPF | F13: 4 | G13: Kg | H13: 25 | I13: =F13*H13 -> 100 | K13: 6500 | M13: =K13*L13 -> 0 | N13: =K13+M13 -> 6500 | P13: 44810 | R13: PO / NBF / 060922 / 03 | T13: Stats Speciality Products
A14: 6 | B14: 44809 | D14: ENRA GUARD | F14: 8 | G14: Kg | H14: 25 | I14: =F14*H14 -> 200 | M14: =K14*L14 -> 0 | N14: =K14+M14 -> 0 | R14: PO / NBF / | T14: Supplied from Hitech Kolkata
A15: 7 | B15: 44809 | D15: KOLIN-PLUS instead of BIOCHOLINE | F15: 20 | G15: Kg | H15: 25 | I15: =F15*H15 -> 500 | K15: 1750 | M15: =K15*L15 -> 0 | N15: =K15+M15 -> 1750 | P15: 44810 | R15: PO / NBF / 060922 / 02 | T15: Das Drug Centre, Habra
A16: 8 | B16: 44817 | D16: TRACEMIN-BB | F16: =500/25 -> 20 | G16: Kg | H16: 25 | I16: =F16*H16 -> 500 | K16: 1750 | M16: =K16*L16 -> 0 | N16: =K16+M16 -> 1750 | P16: 44818 | R16: PO / NBF / 140922 / 01 | T16: B V Biocrop - Hitech Division
A17: 9 | B17: 44817 | D17: KEMZYME - XPF | F17: 8 | G17: Kg | H17: 25 | I17: =F17*H17 -> 200 | K17: 6500 | M17: =K17*L17 -> 0 | N17: =K17+M17 -> 6500 | P17: 44818 | R17: PO / NBF / | T17: Not done due to Repeat order
A18: 10 | B18: 44817 | D18: SELCON FORTE | F18: 20 | G18: Kg | H18: 10 | I18: =F18*H18 -> 200 | K18: 4000 | M18: =K18*L18 -> 0 | N18: =K18+M18 -> 4000 | P18: 44818 | R18: PO / NBF / 140922 / 02 | T18: Zeus Biotech Pvt Ltd
A19: 11 | B19: 44817 | D19: OVASTIM | F19: 300 | G19: Kg | H19: 1 | I19: =F19*H19 -> 300 | K19: 400 | M19: =K19*L19 -> 0 | N19: =K19+M19 -> 400 | P19: 44818 | R19: PO / NBF / 140922 / 03 | T19: Izda Health Care
A20: 12 | B20: 44824 | D20: VOLAMEL | F20: 12 | G20: Kg | H20: 25 | I20: =F20*H20 -> 300 | K20: 14250 | M20: =K20*L20 -> 0 | N20: =K20+M20 -> 14250 | P20: 44826 | R20: PO / NBF / 220922 / 01 | T20: APC Nutrients Limited
A21: 13 | B21: 44824 | D21: STODI | F21: 12 | G21: Kg | H21: 25 | I21: =F21*H21 -> 300 | K21: 1775 | M21: =K21*L21 -> 0 | N21: =K21+M21 -> 1775 | P21: 44826 | R21: PO / NBF / 220922 / 02 | T21: Das Drug Centre, Habra
A22: 14 | B22: 44825 | D22: HIPRAVIHAR CLON H-120 | F22: 40 | G22: Dose | H22: 2500 | I22: =F22*H22 -> 100000 | K22: 550 | L22: 0.05 | M22: =K22*L22 -> 27.5 | N22: =K22+M22 -> 577.5 | P22: 44826 | R22: PO / NBF / 220922 / 03 | T22: Tara Enterprises, Hyderabad
A23: 15 | B23: 44827 | D23: RECEPTOL (MSD) | F23: 40 | G23: ML | H23: 10 | I23: =F23*H23 -> 400 | K23: 700 | M23: =K23*L23 -> 0 | N23: =K23+M23 -> 700 | P23: 44827 | R23: PO / NBF / 230922 / 01 | T23: Stats Speciality Products
A24: 16 | B24: 44830 | D24: KAMRAKSHA PLUS | F24: 20 | G24: Ltr | H24: 5 | I24: =F24*H24 -> 100 | K24: 1398.3 | L24: 0.18 | M24: =K24*L24 -> 251.694 | N24: =K24+M24 -> 1649.994 | P24: 44830 | R24: PO / NBF / 260922 / 01 | T24: ABP Enterprises
A25: 17 | B25: 44830 | D25: DEFORCE INJECTION (Idza) | F25: 500 | G25: ML | H25: 1 | I25: =F25*H25 -> 500 | K25: 75 | L25: 0.12 | M25: =K25*L25 -> 9 | N25: =K25+M25 -> 84 | P25: 44830 | R25: PO / NBF / 260922 / 02 | T25: Izda Health Care
A26: 18 | B26: 44830 | D26: AMBIPLEX | F26: 20 | G26: Ltr | H26: 5 | I26: =F26*H26 -> 100 | K26: 515 | M26: =K26*L26 -> 0 | N26: =K26+M26 -> 515 | P26: 44830 | R26: PO / NBF / 260922 / 03 | T26: Das Drug Centre, Habra
A27: 19 | B27: 44830 | D27: URIMIN INJECTION | F27: 30 | G27: ML | H27: 100 | I27: =F27*H27 -> 3000 | K27: 319.24 | L27: 0.05 | M27: =K27*L27 -> 15.962 | N27: =K27+M27 -> 335.202 | P27: 44830 | R27: PO / NBF / 260922 / 03 | T27: Das Drug Centre, Habra
A28: 20 | B28: 44830 | D28: AQUAMAX | F28: 40 | G28: Ltr | H28: 5 | I28: =F28*H28 -> 200 | K28: 457 | L28: 0.18 | M28: =K28*L28 -> 82.26 | N28: =K28+M28 -> 539.26 | P28: 44830 | R28: PO / NBF / 260922 / 04 | T28: B V Biocrop - Hitech Division
A29: 21 | B29: 44830 | D29: B- 904 | F29: 12 | G29: Ltr | H29: 5 | I29: =F29*H29 -> 60 | K29: 3273 | L29: 0.18 | M29: =K29*L29 -> 589.14 | N29: =K29+M29 -> 3862.14 | P29: 44830 | R29: PO / NBF / 260922 / 04 | T29: B V Biocrop - Hitech Division
A30: 22 | B30: 44830 | D30: BIO BUSTER PLUS | F30: 12 | G30: Gms | H30: 500 | I30: =F30*H30 -> 6000 | K30: 405 | L30: 0.18 | M30: =K30*L30 -> 72.9 | N30: =K30+M30 -> 477.9 | P30: 44830 | R30: PO / NBF / 260922 / 04 | T30: B V Biocrop - Hitech Division
A31: 23 | B31: 44849 | D31: BIOPLEX POULTRY PAK | F31: 20 | G31: Kg | H31: 25 | I31: =F31*H31 -> 500 | K31: 5500 | M31: =K31*L31 -> 0 | N31: =K31+M31 -> 5500 | P31: 44851 | R31: PO / NBF / 171022 / 01 | T31: Alltech Biotechnology Pvt Ltd
A32: 24 | B32: 44849 | D32: CLOSTAT - 12 / 365 | F32: 4 | G32: Kg | H32: 25 | I32: =F32*H32 -> 100 | K32: 14000 | M32: =K32*L32 -> 0 | N32: =K32+M32 -> 14000 | P32: 44851 | R32: PO / NBF / 171022 / 02 | T32: Stats Speciality Products
A33: 25 | B33: 44849 | D33: KEMZYME - XPF | F33: 4 | G33: Kg | H33: 25 | I33: =F33*H33 -> 100 | K33: 6500 | M33: =K33*L33 -> 0 | N33: =K33+M33 -> 6500 | P33: 44851 | R33: PO / NBF / 171022 / 02 | T33: Stats Speciality Products
A34: 26 | B34: 44849 | D34: TOXFIN - 365 | F34: 20 | G34: Kg | H34: 25 | I34: =F34*H34 -> 500 | K34: 3500 | M34: =K34*L34 -> 0 | N34: =K34+M34 -> 3500 | P34: 44851 | R34: PO / NBF / 171022 / 02 | T34: Order has been cancelled
A35: 27 | B35: 44849 | D35: MONO CALCIUM PHOSPHATE | G35: Kg | I35: =F35*H35 -> 0 | M35: =K35*L35 -> 0 | N35: =K35+M35 -> 0 | R35: PO / NBF / | T35: Supplied IMPORTED Materials
A36: 28 | B36: P K Das | D36: TOXO - XL | F36: 20 | G36: Kg | H36: 25 | I36: =F36*H36 -> 500 | K36: 5750 | M36: =K36*L36 -> 0 | N36: =K36+M36 -> 5750 | P36: 44856 | R36: PO / NBF / 221022 / 01 | T36: Trouw Nutrition India Pvt Ltd
A37: 29 | B37: 44859 | D37: FORLUTIN - 10% | F37: 20 | G37: Kg | H37: 10 | I37: =F37*H37 -> 200 | K37: 7050 | M37: =K37*L37 -> 0 | N37: =K37+M37 -> 7050 | P37: 44860 | R37: PO / NBF / 261022 / 01 | T37: Stallen South Asia Pvt Ltd
A38: 30 | B38: 44862 | D38: TILMOVET | F38: 18 | G38: ML | H38: 960 | I38: =F38*H38 -> 17280 | K38: 9300 | L38: 0.12 | M38: =K38*L38 -> 1116 | N38: =K38+M38 -> 10416 | P38: 44867 | R38: PO / NBF / 021122 / 01 | T38: Huvephatrma Sea Pune
A39: 31 | B39: 44862 | D39: SANEXT POWDER | F39: 10 | G39: Kg | H39: 1 | I39: =F39*H39 -> 10 | K39: 2600 | L39: 0.18 | M39: =K39*L39 -> 468 | N39: =K39+M39 -> 3068 | P39: 44867 | R39: PO / NBF / 021122 / 02 | T39: Healers Associates
A40: 32 | B40: 44862 | D40: BV CLO-2 (10 Gms) | F40: 20 | G40: Pcs | H40: 50 | I40: =F40*H40 -> 1000 | K40: 1100 | L40: 0.18 | M40: =K40*L40 -> 198 | N40: =K40+M40 -> 1298 | P40: 44867 | R40: PO / NBF / 021122 / 03 | T40: B V Biocrop - Hitech Division
A41: 33 | B41: 44862 | D41: AMO PREMIX | F41: 36 | G41: Gms | H41: 500 | I41: =F41*H41 -> 18000 | K41: 539 | M41: =K41*L41 -> 0 | N41: =K41+M41 -> 539 | P41: 44867 | R41: PO / NBF / 021122 / 04 | T41: Venkys India - AHP Division
A42: 34 | B42: 44862 | D42: ELIMIN - 8 | F42: 12 | G42: Ltr | H42: 5 | I42: =F42*H42 -> 60 | K42: 1238 | M42: =K42*L42 -> 0 | N42: =K42+M42 -> 1238 | P42: 44867 | R42: PO / NBF / 021122 / 04 | T42: Venkys India - AHP Division
A43: 35 | B43: 44867 | D43: BRONCHIN KILLED VACCINE | F43: 13 | G43: Dose | H43: 1000 | I43: =F43*H43 -> 13000 | K43: 2772 | L43: 0.05 | M43: =K43*L43 -> 138.6 | N43: =K43+M43 -> 2910.6 | P43: 44868 | R43: PO / NBF / 031122 / 01 | T43: Crescent Marketing, Hyderabad
A44: 36 | B44: 44862 | D44: KAYSOL FORTE | F44: 80 | G44: Gms | H44: 50 | I44: =F44*H44 -> 4000 | K44: 65 | M44: =K44*L44 -> 0 | N44: =K44+M44 -> 65 | P44: 44868 | R44: PO / NBF / 031122 / 02 | T44: Das Drug Centre, Habra
A45: 37 | B45: 44862 | D45: VVAANDOX | F45: 80 | G45: Gms | H45: 250 | I45: =F45*H45 -> 20000 | K45: 400 | L45: 0.12 | M45: =K45*L45 -> 48 | N45: =K45+M45 -> 448 | P45: 44868 | R45: PO / NBF / 031122 / 02 | T45: Das Drug Centre, Habra
...

Sheet Account Details Aug22-Mar23
B3: NBF | E3: ORDER DETAILS AS PER INDENT OF NARAENDRA BREEDING FARMS | S3: Update as on 30.03.2023
B5: INDENT | D5: HITECH BREEDING FARMS | F5: D E T A I L S A B O U T I T E M | K5: D E T A I L S A B O U T O R D E R | P5: D E T A I L S A B O U T P A Y M E N T
B7: PURCHASE ORDER DATE | D7: NAME OF SUPPLIER | F7: ITEM DESCRIPTION | H7: UOM | I7: OREDR QTY | K7: PO DATE & PO NO | N7: Payable Amount | P7: GRN DATE | Q7: GRN NO | R7: CR LIMIT | S7: PAYMENT SCHEDULE | T7: DATE OF PAYMENT | U7: PAYMENT AMOUNT
P8: mm/dd/yy | T8: mm/dd/yy
A9: 1 | B9: =+'Order Details Aug22-Mar23'!P9 -> 44803 | D9: =+'Order Details Aug22-Mar23'!T9 -> We Care Animal Health | F9: =+'Order Details Aug22-Mar23'!D9 -> FLYVIN | H9: =+'Order Details Aug22-Mar23'!G9 -> Kg | I9: =+'Order Details Aug22-Mar23'!I9 -> 70 | K9: =+'Order Details Aug22-Mar23'!R9 -> PO / NBF / 300822/ 01 | N9: =+'Order Details Aug22-Mar23'!F9*'Order Details Aug22-Mar23'!N9 -> 50400 | R9: 7 | S9: =P9+R9 -> 7 | U9: 50400
A10: 2 | D10: =+'Order Details Aug22-Mar23'!T10 -> Supplied from Hitech Kolkata | F10: =+'Order Details Aug22-Mar23'!D10 -> DLM | H10: =+'Order Details Aug22-Mar23'!G10 -> Kg | I10: =+'Order Details Aug22-Mar23'!I10 -> 500 | N10: =+'Order Details Aug22-Mar23'!F10*'Order Details Aug22-Mar23'!N10 -> 0 | R10: N A | S10: =P10+R10 -> #VALUE!
A11: 3 | B11: =+'Order Details Aug22-Mar23'!P11 -> 44810 | D11: =+'Order Details Aug22-Mar23'!T11 -> Avitech Nutrition Pvt Ltd | F11: =+'Order Details Aug22-Mar23'!D11 -> BREEDER VITAMIN PREMIX-HYD | H11: =+'Order Details Aug22-Mar23'!G11 -> Kg | I11: =+'Order Details Aug22-Mar23'!I11 -> 500 | K11: =+'Order Details Aug22-Mar23'!R11 -> PO / NBF / 060922 / 01 | N11: =+'Order Details Aug22-Mar23'!F11*'Order Details Aug22-Mar23'!N11 -> 362000 | R11: 3 | S11: =P11+R11 -> 3
A12: 4 | D12: =+'Order Details Aug22-Mar23'!T12 -> Supplied from Hitech Kolkata | F12: =+'Order Details Aug22-Mar23'!D12 -> ALKAKARB (Sodi Bicarb) | H12: =+'Order Details Aug22-Mar23'!G12 -> Kg | I12: =+'Order Details Aug22-Mar23'!I12 -> 1500 | N12: =+'Order Details Aug22-Mar23'!F12*'Order Details Aug22-Mar23'!N12 -> 0 | R12: N A | S12: =P12+R12 -> #VALUE!
A13: 5 | B13: =+'Order Details Aug22-Mar23'!P13 -> 44810 | D13: =+'Order Details Aug22-Mar23'!T13 -> Stats Speciality Products | F13: =+'Order Details Aug22-Mar23'!D13 -> KEMZYME - XPF | H13: =+'Order Details Aug22-Mar23'!G13 -> Kg | I13: =+'Order Details Aug22-Mar23'!I13 -> 100 | K13: =+'Order Details Aug22-Mar23'!R13 -> PO / NBF / 060922 / 03 | N13: =+'Order Details Aug22-Mar23'!F13*'Order Details Aug22-Mar23'!N13 -> 26000 | R13: 45 | S13: =P13+R13 -> 45
A14: 6 | D14: =+'Order Details Aug22-Mar23'!T14 -> Supplied from Hitech Kolkata | F14: =+'Order Details Aug22-Mar23'!D14 -> ENRA GUARD | H14: =+'Order Details Aug22-Mar23'!G14 -> Kg | I14: =+'Order Details Aug22-Mar23'!I14 -> 200 | N14: =+'Order Details Aug22-Mar23'!F14*'Order Details Aug22-Mar23'!N14 -> 0 | R14: N A | S14: =P14+R14 -> #VALUE!
A15: 7 | B15: =+'Order Details Aug22-Mar23'!P15 -> 44810 | D15: =+'Order Details Aug22-Mar23'!T15 -> Das Drug Centre, Habra | F15: =+'Order Details Aug22-Mar23'!D15 -> KOLIN-PLUS instead of BIOCHOLINE | H15: =+'Order Details Aug22-Mar23'!G15 -> Kg | I15: =+'Order Details Aug22-Mar23'!I15 -> 500 | K15: =+'Order Details Aug22-Mar23'!R15 -> PO / NBF / 060922 / 02 | N15: =+'Order Details Aug22-Mar23'!F15*'Order Details Aug22-Mar23'!N15 -> 35000 | R15: 45 | S15: =P15+R15 -> 45
A16: 8 | B16: =+'Order Details Aug22-Mar23'!P16 -> 44818 | D16: =+'Order Details Aug22-Mar23'!T16 -> B V Biocrop - Hitech Division | F16: =+'Order Details Aug22-Mar23'!D16 -> TRACEMIN-BB | H16: =+'Order Details Aug22-Mar23'!G16 -> Kg | I16: =+'Order Details Aug22-Mar23'!I16 -> 500 | K16: =+'Order Details Aug22-Mar23'!R16 -> PO / NBF / 140922 / 01 | N16: =+'Order Details Aug22-Mar23'!F16*'Order Details Aug22-Mar23'!N16 -> 35000 | R16: 7 | S16: =P16+R16 -> 7
A17: 9 | B17: =+'Order Details Aug22-Mar23'!P17 -> 44818 | D17: =+'Order Details Aug22-Mar23'!T17 -> Not done due to Repeat order | F17: =+'Order Details Aug22-Mar23'!D17 -> KEMZYME - XPF | H17: =+'Order Details Aug22-Mar23'!G17 -> Kg | I17: =+'Order Details Aug22-Mar23'!I17 -> 200 | N17: =+'Order Details Aug22-Mar23'!F17*'Order Details Aug22-Mar23'!N17 -> 52000 | R17: N A | S17: =P17+R17 -> #VALUE!
A18: 10 | B18: =+'Order Details Aug22-Mar23'!P18 -> 44818 | D18: =+'Order Details Aug22-Mar23'!T18 -> Zeus Biotech Pvt Ltd | F18: =+'Order Details Aug22-Mar23'!D18 -> SELCON FORTE | H18: =+'Order Details Aug22-Mar23'!G18 -> Kg | I18: =+'Order Details Aug22-Mar23'!I18 -> 200 | K18: =+'Order Details Aug22-Mar23'!R18 -> PO / NBF / 140922 / 02 | N18: =+'Order Details Aug22-Mar23'!F18*'Order Details Aug22-Mar23'!N18 -> 80000 | R18: 45 | S18: =P18+R18 -> 45
A19: 11 | B19: =+'Order Details Aug22-Mar23'!P19 -> 44818 | D19: =+'Order Details Aug22-Mar23'!T19 -> Izda Health Care | F19: =+'Order Details Aug22-Mar23'!D19 -> OVASTIM | H19: =+'Order Details Aug22-Mar23'!G19 -> Kg | I19: =+'Order Details Aug22-Mar23'!I19 -> 300 | K19: =+'Order Details Aug22-Mar23'!R19 -> PO / NBF / 140922 / 03 | N19: =+'Order Details Aug22-Mar23'!F19*'Order Details Aug22-Mar23'!N19 -> 120000 | R19: 45 | S19: =P19+R19 -> 45
A20: 12 | B20: =+'Order Details Aug22-Mar23'!P20 -> 44826 | D20: =+'Order Details Aug22-Mar23'!T20 -> APC Nutrients Limited | F20: =+'Order Details Aug22-Mar23'!D20 -> VOLAMEL | H20: =+'Order Details Aug22-Mar23'!G20 -> Kg | I20: =+'Order Details Aug22-Mar23'!I20 -> 300 | K20: =+'Order Details Aug22-Mar23'!R20 -> PO / NBF / 220922 / 01 | N20: =+'Order Details Aug22-Mar23'!F20*'Order Details Aug22-Mar23'!N20 -> 171000 | R20: 3 | S20: =P20+R20 -> 3
A21: 13 | B21: =+'Order Details Aug22-Mar23'!P21 -> 44826 | D21: =+'Order Details Aug22-Mar23'!T21 -> Das Drug Centre, Habra | F21: =+'Order Details Aug22-Mar23'!D21 -> STODI | H21: =+'Order Details Aug22-Mar23'!G21 -> Kg | I21: =+'Order Details Aug22-Mar23'!I21 -> 300 | K21: =+'Order Details Aug22-Mar23'!R21 -> PO / NBF / 220922 / 02 | N21: =+'Order Details Aug22-Mar23'!F21*'Order Details Aug22-Mar23'!N21 -> 21300 | R21: 45 | S21: =P21+R21 -> 45
A22: 14 | B22: =+'Order Details Aug22-Mar23'!P22 -> 44826 | D22: =+'Order Details Aug22-Mar23'!T22 -> Tara Enterprises, Hyderabad | F22: =+'Order Details Aug22-Mar23'!D22 -> HIPRAVIHAR CLON H-120 | H22: =+'Order Details Aug22-Mar23'!G22 -> Dose | I22: =+'Order Details Aug22-Mar23'!I22 -> 100000 | K22: =+'Order Details Aug22-Mar23'!R22 -> PO / NBF / 220922 / 03 | N22: =+'Order Details Aug22-Mar23'!F22*'Order Details Aug22-Mar23'!N22 -> 23100 | R22: 45 | S22: =P22+R22 -> 45
A23: 15 | B23: =+'Order Details Aug22-Mar23'!P23 -> 44827 | D23: =+'Order Details Aug22-Mar23'!T23 -> Stats Speciality Products | F23: =+'Order Details Aug22-Mar23'!D23 -> RECEPTOL (MSD) | H23: =+'Order Details Aug22-Mar23'!G23 -> ML | I23: =+'Order Details Aug22-Mar23'!I23 -> 400 | K23: =+'Order Details Aug22-Mar23'!R23 -> PO / NBF / 230922 / 01 | N23: =+'Order Details Aug22-Mar23'!F23*'Order Details Aug22-Mar23'!N23 -> 28000 | R23: 45 | S23: =P23+R23 -> 45
A24: 16 | B24: =+'Order Details Aug22-Mar23'!P24 -> 44830 | D24: =+'Order Details Aug22-Mar23'!T24 -> ABP Enterprises | F24: =+'Order Details Aug22-Mar23'!D24 -> KAMRAKSHA PLUS | H24: =+'Order Details Aug22-Mar23'!G24 -> Ltr | I24: =+'Order Details Aug22-Mar23'!I24 -> 100 | K24: =+'Order Details Aug22-Mar23'!R24 -> PO / NBF / 260922 / 01 | N24: =+'Order Details Aug22-Mar23'!F24*'Order Details Aug22-Mar23'!N24 -> 32999.88 | R24: 10 | S24: =P24+R24 -> 10
A25: 17 | B25: =+'Order Details Aug22-Mar23'!P25 -> 44830 | D25: =+'Order Details Aug22-Mar23'!T25 -> Izda Health Care | F25: =+'Order Details Aug22-Mar23'!D25 -> DEFORCE INJECTION (Idza) | H25: =+'Order Details Aug22-Mar23'!G25 -> ML | I25: =+'Order Details Aug22-Mar23'!I25 -> 500 | K25: =+'Order Details Aug22-Mar23'!R25 -> PO / NBF / 260922 / 02 | N25: =+'Order Details Aug22-Mar23'!F25*'Order Details Aug22-Mar23'!N25 -> 42000 | R25: 45 | S25: =P25+R25 -> 45
A26: 18 | B26: =+'Order Details Aug22-Mar23'!P26 -> 44830 | D26: =+'Order Details Aug22-Mar23'!T26 -> Das Drug Centre, Habra | F26: =+'Order Details Aug22-Mar23'!D26 -> AMBIPLEX | H26: =+'Order Details Aug22-Mar23'!G26 -> Ltr | I26: =+'Order Details Aug22-Mar23'!I26 -> 100 | K26: =+'Order Details Aug22-Mar23'!R26 -> PO / NBF / 260922 / 03 | N26: =+'Order Details Aug22-Mar23'!F26*'Order Details Aug22-Mar23'!N26 -> 10300 | R26: 45 | S26: =P26+R26 -> 45
A27: 19 | B27: =+'Order Details Aug22-Mar23'!P27 -> 44830 | D27: =+'Order Details Aug22-Mar23'!T27 -> Das Drug Centre, Habra | F27: =+'Order Details Aug22-Mar23'!D27 -> URIMIN INJECTION | H27: =+'Order Details Aug22-Mar23'!G27 -> ML | I27: =+'Order Details Aug22-Mar23'!I27 -> 3000 | K27: =+'Order Details Aug22-Mar23'!R27 -> PO / NBF / 260922 / 03 | N27: =+'Order Details Aug22-Mar23'!F27*'Order Details Aug22-Mar23'!N27 -> 10056.06 | R27: 45 | S27: =P27+R27 -> 45
A28: 20 | B28: =+'Order Details Aug22-Mar23'!P28 -> 44830 | D28: =+'Order Details Aug22-Mar23'!T28 -> B V Biocrop - Hitech Division | F28: =+'Order Details Aug22-Mar23'!D28 -> AQUAMAX | H28: =+'Order Details Aug22-Mar23'!G28 -> Ltr | I28: =+'Order Details Aug22-Mar23'!I28 -> 200 | K28: =+'Order Details Aug22-Mar23'!R28 -> PO / NBF / 260922 / 04 | N28: =+'Order Details Aug22-Mar23'!F28*'Order Details Aug22-Mar23'!N28 -> 21570.4 | R28: 7 | S28: =P28+R28 -> 7
A29: 21 | B29: =+'Order Details Aug22-Mar23'!P29 -> 44830 | D29: =+'Order Details Aug22-Mar23'!T29 -> B V Biocrop - Hitech Division | F29: =+'Order Details Aug22-Mar23'!D29 -> B- 904 | H29: =+'Order Details Aug22-Mar23'!G29 -> Ltr | I29: =+'Order Details Aug22-Mar23'!I29 -> 60 | K29: =+'Order Details Aug22-Mar23'!R29 -> PO / NBF / 260922 / 04 | N29: =+'Order Details Aug22-Mar23'!F29*'Order Details Aug22-Mar23'!N29 -> 46345.68 | R29: 7 | S29: =P29+R29 -> 7
... A34: 26 | B34: =+'Order Details Aug22-Mar23'!P34 -> 44851 | D34: =+'Order Details Aug22-Mar23'!T34 -> Order has been cancelled | F34: =+'Order Details Aug22-Mar23'!D34 -> TOXFIN - 365 | H34: =+'Order Details Aug22-Mar23'!G34 -> Kg | I34: =+'Order Details Aug22-Mar23'!I34 -> 500 | K34: =+'Order Details Aug22-Mar23'!R34 -> PO / NBF / 171022 / 02 | N34: =+'Order Details Aug22-Mar23'!F34*'Order Details Aug22-Mar23'!N34 -> 70000 | R34: 45 | S34: =P34+R34 -> 45
A35: 27 | D35: =+'Order Details Aug22-Mar23'!T35 -> Supplied IMPORTED Materials | F35: =+'Order Details Aug22-Mar23'!D35 -> MONO CALCIUM PHOSPHATE | H35: =+'Order Details Aug22-Mar23'!G35 -> Kg | I35: =+'Order Details Aug22-Mar23'!I35 -> 0 | N35: =+'Order Details Aug22-Mar23'!F35*'Order Details Aug22-Mar23'!N35 -> 0 | R35: N A | S35: =P35+R35 -> #VALUE!
A36: 28 | B36: =+'Order Details Aug22-Mar23'!P36 -> 44856 | D36: =+'Order Details Aug22-Mar23'!T36 -> Trouw Nutrition India Pvt Ltd | F36: =+'Order Details Aug22-Mar23'!D36 -> TOXO - XL | H36: =+'Order Details Aug22-Mar23'!G36 -> Kg | I36: =+'Order Details Aug22-Mar23'!I36 -> 500 | K36: =+'Order Details Aug22-Mar23'!R36 -> PO / NBF / 221022 / 01 | N36: =+'Order Details Aug22-Mar23'!F36*'Order Details Aug22-Mar23'!N36 -> 115000 | R36: 45 | S36: =P36+R36 -> 45
A37: 29 | B37: =+'Order Details Aug22-Mar23'!P37 -> 44860 | D37: =+'Order Details Aug22-Mar23'!T37 -> Stallen South Asia Pvt Ltd | F37: =+'Order Details Aug22-Mar23'!D37 -> FORLUTIN - 10% | H37: =+'Order Details Aug22-Mar23'!G37 -> Kg | I37: =+'Order Details Aug22-Mar23'!I37 -> 200 | K37: =+'Order Details Aug22-Mar23'!R37 -> PO / NBF / 261022 / 01 | N37: =+'Order Details Aug22-Mar23'!F37*'Order Details Aug22-Mar23'!N37 -> 141000 | R37: 45 | S37: =P37+R37 -> 45
A38: 30 | B38: =+'Order Details Aug22-Mar23'!P38 -> 44867 | D38: =+'Order Details Aug22-Mar23'!T38 -> Huvephatrma Sea Pune | F38: =+'Order Details Aug22-Mar23'!D38 -> TILMOVET | H38: =+'Order Details Aug22-Mar23'!G38 -> ML | I38: =+'Order Details Aug22-Mar23'!I38 -> 17280 | K38: =+'Order Details Aug22-Mar23'!R38 -> PO / NBF / 021122 / 01 | N38: =+'Order Details Aug22-Mar23'!F38*'Order Details Aug22-Mar23'!N38 -> 187488 | R38: 45 | S38: =P38+R38 -> 45
A39: 31 | B39: =+'Order Details Aug22-Mar23'!P39 -> 44867 | D39: =+'Order Details Aug22-Mar23'!T39 -> Healers Associates | F39: =+'Order Details Aug22-Mar23'!D39 -> SANEXT POWDER | H39: =+'Order Details Aug22-Mar23'!G39 -> Kg | I39: =+'Order Details Aug22-Mar23'!I39 -> 10 | K39: =+'Order Details Aug22-Mar23'!R39 -> PO / NBF / 021122 / 02 | N39: =+'Order Details Aug22-Mar23'!F39*'Order Details Aug22-Mar23'!N39 -> 30680 | R39: 45 | S39: =P39+R39 -> 45
A40: 32 | B40: =+'Order Details Aug22-Mar23'!P40 -> 44867 | D40: =+'Order Details Aug22-Mar23'!T40 -> B V Biocrop - Hitech Division | F40: =+'Order Details Aug22-Mar23'!D40 -> BV CLO-2 (10 Gms) | H40: =+'Order Details Aug22-Mar23'!G40 -> Pcs | I40: =+'Order Details Aug22-Mar23'!I40 -> 1000 | K40: =+'Order Details Aug22-Mar23'!R40 -> PO / NBF / 021122 / 03 | N40: =+'Order Details Aug22-Mar23'!F40*'Order Details Aug22-Mar23'!N40 -> 25960 | R40: 7 | S40: =P40+R40 -> 7
A41: 33 | B41: =+'Order Details Aug22-Mar23'!P41 -> 44867 | D41: =+'Order Details Aug22-Mar23'!T41 -> Venkys India - AHP Division | F41: =+'Order Details Aug22-Mar23'!D41 -> AMO PREMIX | H41: =+'Order Details Aug22-Mar23'!G41 -> Gms | I41: =+'Order Details Aug22-Mar23'!I41 -> 18000 | K41: =+'Order Details Aug22-Mar23'!R41 -> PO / NBF / 021122 / 04 | N41: =+'Order Details Aug22-Mar23'!F41*'Order Details Aug22-Mar23'!N41 -> 19404 | R41: 7 | S41: =P41+R41 -> 7
A42: 34 | B42: =+'Order Details Aug22-Mar23'!P42 -> 44867 | D42: =+'Order Details Aug22-Mar23'!T42 -> Venkys India - AHP Division | F42: =+'Order Details Aug22-Mar23'!D42 -> ELIMIN - 8 | H42: =+'Order Details Aug22-Mar23'!G42 -> Ltr | I42: =+'Order Details Aug22-Mar23'!I42 -> 60 | K42: =+'Order Details Aug22-Mar23'!R42 -> PO / NBF / 021122 / 04 | N42: =+'Order Details Aug22-Mar23'!F42*'Order Details Aug22-Mar23'!N42 -> 14856 | R42: 7 | S42: =P42+R42 -> 7
A43: 35 | B43: =+'Order Details Aug22-Mar23'!P43 -> 44868 | D43: =+'Order Details Aug22-Mar23'!T43 -> Crescent Marketing, Hyderabad | F43: =+'Order Details Aug22-Mar23'!D43 -> BRONCHIN KILLED VACCINE | H43: =+'Order Details Aug22-Mar23'!G43 -> Dose | I43: =+'Order Details Aug22-Mar23'!I43 -> 13000 | K43: =+'Order Details Aug22-Mar23'!R43 -> PO / NBF / 031122 / 01 | N43: =+'Order Details Aug22-Mar23'!F43*'Order Details Aug22-Mar23'!N43 -> 37837.8 | R43: 45 | S43: =P43+R43 -> 45
A44: 36 | B44: =+'Order Details Aug22-Mar23'!P44 -> 44868 | D44: =+'Order Details Aug22-Mar23'!T44 -> Das Drug Centre, Habra | F44: =+'Order Details Aug22-Mar23'!D44 -> KAYSOL FORTE | H44: =+'Order Details Aug22-Mar23'!G44 -> Gms | I44: =+'Order Details Aug22-Mar23'!I44 -> 4000 | K44: =+'Order Details Aug22-Mar23'!R44 -> PO / NBF / 031122 / 02 | N44: =+'Order Details Aug22-Mar23'!F44*'Order Details Aug22-Mar23'!N44 -> 5200 | R44: 45 | S44: =P44+R44 -> 45
A45: 37 | B45: =+'Order Details Aug22-Mar23'!P45 -> 44868 | D45: =+'Order Details Aug22-Mar23'!T45 -> Das Drug Centre, Habra | F45: =+'Order Details Aug22-Mar23'!D45 -> VVAANDOX | H45: =+'Order Details Aug22-Mar23'!G45 -> Gms | I45: =+'Order Details Aug22-Mar23'!I45 -> 20000 | K45: =+'Order Details Aug22-Mar23'!R45 -> PO / NBF / 031122 / 02 | N45: =+'Order Details Aug22-Mar23'!F45*'Order Details Aug22-Mar23'!N45 -> 35840 | R45: 45 | S45: =P45+R45 -> 45
A46: 38 | B46: =+'Order Details Aug22-Mar23'!P46 -> 44868 | D46: =+'Order Details Aug22-Mar23'!T46 -> Hester Biosciences Limited | F46: =+'Order Details Aug22-Mar23'!D46 -> IB MA-5 LIVE Vaccine | H46: =+'Order Details Aug22-Mar23'!G46 -> Dose | I46: =+'Order Details Aug22-Mar23'!I46 -> 27000 | K46: =+'Order Details Aug22-Mar23'!R46 -> PO / NBF / 031122 / 03 | N46: =+'Order Details Aug22-Mar23'!F46*'Order Details Aug22-Mar23'!N46 -> 7087.5 | R46: 7 | S46: =P46+R46 -> 7
A47: 39 | B47: =+'Order Details Aug22-Mar23'!P47 -> 44868 | D47: =+'Order Details Aug22-Mar23'!T47 -> Hester Biosciences Limited | F47: =+'Order Details Aug22-Mar23'!D47 -> ILT LIVE (GI-10000) | H47: =+'Order Details Aug22-Mar23'!G47 -> Dose | I47: =+'Order Details Aug22-Mar23'!I47 -> 54000 | K47: =+'Order Details Aug22-Mar23'!R47 -> PO / NBF / 031122 / 03 | N47: =+'Order Details Aug22-Mar23'!F47*'Order Details Aug22-Mar23'!N47 -> 85050 | R47: 7 | S47: =P47+R47 -> 7
... A92: 84 | B92: =+'Order Details Aug22-Mar23'!P92 -> 44907 | D92: =+'Order Details Aug22-Mar23'!T92 -> Arevin Lifesciences Pvt Ltd | F92: =+'Order Details Aug22-Mar23'!D92 -> MICROVIT-E 50 Promix (Adisseo) | H92: =+'Order Details Aug22-Mar23'!G92 -> Kg | I92: =+'Order Details Aug22-Mar23'!I92 -> 200 | K92: =+'Order Details Aug22-Mar23'!R92 -> PO / NBF / 121222 / 10 | N92: =+'Order Details Aug22-Mar23'!F92*'Order Details Aug22-Mar23'!N92 -> 192000 | R92: 45 | S92: =P92+R92 -> 45
...

Sheet Order Details Apr23-Mar24
B3: NBF | E3: ORDER DETAILS AS PER INDENT OF NARAENDRA BREEDING FARMS | S3: Update as on 30.03.2024
B5: INDENT | D5: NARAENDRA BREEDING FARMS | F5: D E T A I L S A B O U T I T E M | K5: D E T A I L S A B O U T P R I C E | P5: D E T A I L S A B O U T P U R C H A S E O R D E R
B7: DATE OF INDENT | D7: NAME OF ITEM | F7: REQUIRE QTY | G7: UOM | H7: PACK SIZE | I7: OREDR QTY | K7: PRICE | L7: GST % | M7: GST Crgs | N7: NET PRICE | P7: PO RAISED ON | R7: PO DATE / NO | T7: NAME OF SUPPLIER
A9: 1 | B9: 45021 | D9: VOLAMEL (Nukamel) | F9: 20 | G9: Kg | H9: 25 | I9: =F9*H9 -> 500 | K9: 14250 | M9: =K9*L9 -> 0 | N9: =K9+M9 -> 14250 | P9: 45022 | R9: PO / NBF / 060423 / 01 | T9: APC Nutrients Limited
A10: 2 | B10: 45021 | D10: MG BAC KILLED VAC (Zoetis) | F10: 22 | G10: Dose | H10: 1000 | I10: =F10*H10 -> 22000 | K10: 6650 | L10: 0.05 | M10: =K10*L10 -> 332.5 | N10: =K10+M10 -> 6982.5 | P10: 45022 | R10: PO / NBF / 060423 / 02 | T10: Das Drug Centre, Habra
A11: 3 | B11: 45021 | D11: MASTERSORB (EW Nutrition) | F11: 20 | G11: Kg | H11: 25 | I11: =F11*H11 -> 500 | K11: 3200 | M11: =K11*L11 -> 0 | N11: =K11+M11 -> 3200 | P11: 45022 | R11: PO / NBF / 060423 / 03 | T11: PP & B Mart Pvt Ltd, Habra
A12: 4 | B12: 45022 | D12: ND KILLED (Visa-15) VAC | F12: 44 | G12: Dose | H12: 1000 | I12: =F12*H12 -> 44000 | K12: 1025 | L12: 0.05 | M12: =K12*L12 -> 51.25 | N12: =K12+M12 -> 1076.25 | P12: 45022 | R12: PO / NBF / 060423 / 04 | T12: Venkateshwara Hatcheries Ltd
A13: 5 | B13: 45023 | D13: TRITYL - 62.5 (Alivira) | F13: 32 | G13: Gms | H13: 400 | I13: =F13*H13 -> 12800 | K13: 8550 | L13: 0.12 | M13: =K13*L13 -> 1026 | N13: =K13+M13 -> 9576 | P13: 45024 | R13: PO / NBF / 080423 / 05 | T13: Alivira Animal Health Ltd
A14: 6 | B14: 45023 | D14: BIO BUSTER PLUS (B V Biocrop) | F14: 60 | G14: Gms | H14: 500 | I14: =F14*H14 -> 30000 | K14: 405 | L14: 0.18 | M14: =K14*L14 -> 72.9 | N14: =K14+M14 -> 477.9 | P14: 45024 | R14: PO / NBF / 080423 / 06 | T14: B V Biocrop, Hitech Division
A15: 7 | B15: 45023 | D15: BAYROCIN (Elanco) | F15: 20 | G15: Ltr | H15: 5 | I15: =F15*H15 -> 100 | K15: 2765 | L15: 0.18 | M15: =K15*L15 -> 497.7 | N15: =K15+M15 -> 3262.7 | P15: 45024 | R15: PO / NBF / 080423 / 07 | T15: Das Drug Centre, Habra
A16: 8 | B16: 45023 | D16: EKTOMIN (Elanco) | F16: 50 | G16: Ltr | H16: 1 | I16: =F16*H16 -> 50 | K16: 600 | L16: 0.12 | M16: =K16*L16 -> 72 | N16: =K16+M16 -> 672 | P16: 45024 | R16: PO / NBF / 080423 / 07 | T16: Das Drug Centre, Habra
A17: 9 | B17: 45023 | D17: FAMITONE (Zenex AH) | F17: 60 | G17: Ltr | H17: 1 | I17: =F17*H17 -> 60 | K17: 580 | M17: =K17*L17 -> 0 | N17: =K17+M17 -> 580 | P17: 45024 | R17: PO / NBF / 080423 / 07 | T17: Das Drug Centre, Habra
A18: 10 | B18: 45028 | D18: INACTIVATED ND (LPAI) | F18: 70 | G18: Dose | H18: 1000 | I18: =F18*H18 -> 70000 | K18: 902.48 | L18: 0.05 | M18: =K18*L18 -> 45.124 | N18: =K18+M18 -> 947.604 | P18: 45030 | R18: PO / NBF / 140423 / 08 | T18: Hester Biosciences Limited
A19: 11 | B19: 45033 | D19: SPERMED (Medichem Product) | F19: 30 | G19: Kg | H19: 1 | I19: =F19*H19 -> 30 | K19: 3500 | M19: =K19*L19 -> 0 | N19: =K19+M19 -> 3500 | P19: 45033 | R19: PO / NBF / 170423 / 09 | T19: Healers Associates, Vijayawada
A20: 12 | B20: 45033 | D20: BIO D - 100 (Huvepharma) | F20: 20 | G20: Kg | H20: 20 | I20: =F20*H20 -> 400 | K20: 32000 | M20: =K20*L20 -> 0 | N20: =K20+M20 -> 32000 | P20: 45033 | R20: PO / NBF / 170423 / 10 | T20: Huve Pharma Sea Pune Pvt Ltd
A21: 13 | B21: 45033 | D21: OVASTIM (Izda Healthcare) | F21: 500 | G21: Kg | H21: 1 | I21: =F21*H21 -> 500 | K21: 400 | M21: =K21*L21 -> 0 | N21: =K21+M21 -> 400 | P21: 45033 | R21: PO / NBF / 170423 / 11 | T21: Izda Healthcare, Ambala Cantonment
A22: 14 | B22: 45033 | D22: SELCON FORTE (Zeus Biotech) | F22: 15 | G22: Kg | H22: 10 | I22: =F22*H22 -> 150 | K22: 4000 | M22: =K22*L22 -> 0 | N22: =K22+M22 -> 4000 | P22: 45033 | R22: PO / NBF / 170423 / 12 | T22: Zeus Biotech Pvt Ltd, Mysore
A23: 15 | B23: 45036 | D23: ND KILLED (Visa-15) VAC | F23: 49 | G23: Dose | H23: 1000 | I23: =F23*H23 -> 49000 | K23: 1025 | L23: 0.05 | M23: =K23*L23 -> 51.25 | N23: =K23+M23 -> 1076.25 | P23: 45036 | R23: PO / NBF / 200423 / 13 | T23: Venkateshwara Hatcheries Ltd
A24: 16 | B24: 45040 | D24: FORLUTIN-10% (Stallen) | F24: 20 | G24: Kg | H24: 10 | I24: =F24*H24 -> 200 | K24: 7050 | M24: =K24*L24 -> 0 | N24: =K24+M24 -> 7050 | P24: 45040 | R24: PO / NBF / 240423 / 14 | T24: Stallen South Asia Pvt Ltd
A25: 17 | B25: 45040 | D25: HEPATOCARE PREMIX (Varsha) | F25: 20 | G25: Kg | H25: 25 | I25: =F25*H25 -> 500 | K25: 1250 | M25: =K25*L25 -> 0 | N25: =K25+M25 -> 1250 | P25: 45040 | R25: PO / NBF / 240423 / 15 | T25: Varsha Multitech, Bangallore
A26: 18 | B26: 45040 | D26: TIAMU-MED (Medichem Product) | F26: 8 | G26: Kg | H26: 25 | I26: =F26*H26 -> 200 | K26: 16875 | M26: =K26*L26 -> 0 | N26: =K26+M26 -> 16875 | P26: 45041 | R26: PO / NBF / 250423 / 16 | T26: Healers Associates, Vijayawada
A27: 19 | B27: 45044 | D27: SALCOCHEK (Ayurvet) | F27: 8 | G27: Kg | H27: 25 | I27: =F27*H27 -> 200 | K27: 3200 | L27: 0.12 | M27: =K27*L27 -> 384 | N27: =K27+M27 -> 3584 | P27: 45045 | R27: PO / NBF / 290423 / 17 | T27: Sai Kiran Medical Agencies
A28: 20 | B28: 45048 | D28: Breeder Vitamin Premix (Custom) | F28: 20 | G28: Kg | H28: 25 | I28: =F28*H28 -> 500 | K28: 14625 | M28: =K28*L28 -> 0 | N28: =K28+M28 -> 14625 | P28: 45050 | R28: PO / NBF / 040523 / 18 | T28: Trouw Nutrition India Pvt Ltd
A29: 21 | B29: 45054 | D29: Hipraviar Clon H-120 (Hipra) | F29: 100 | G29: Dose | H29: 2500 | I29: =F29*H29 -> 250000 | K29: 550 | L29: 0.05 | M29: =K29*L29 -> 27.5 | N29: =K29+M29 -> 577.5 | P29: 45054 | R29: PO / NBF / 080523 / 19 | T29: Tara Enterprises, Hyderabad
A30: 22 | B30: VERBAL | D30: CLOSTAT-365 / 12 (Kemin Indus) | F30: 8 | G30: Kg | H30: 25 | I30: =F30*H30 -> 200 | K30: 12500 | M30: =K30*L30 -> 0 | N30: =K30+M30 -> 12500 | P30: 45057 | R30: PO / NBF / 110523 / 20 | T30: Kemin Industries South Asia
A31: 23 | B31: 45061 | D31: CITRINAL (Alivira) | F31: 25 | G31: Kg | H31: 20 | I31: =F31*H31 -> 500 | K31: 3000 | M31: =K31*L31 -> 0 | N31: =K31+M31 -> 3000 | P31: 45061 | R31: PO / NBF / 150523 / 21 | T31: Alivira Animal Health Ltd
A32: 24 | B32: 45060 | D32: ILT(GI- 10000) Live Vaccine | F32: 42 | G32: Dose | H32: 1000 | I32: =F32*H32 -> 42000 | K32: 1500 | L32: 0.05 | M32: =K32*L32 -> 75 | N32: =K32+M32 -> 1575 | P32: 45060 | R32: PO / NBF / 150523 / 22 | T32: Hester Biosciences Limited
A33: 25 | B33: 45061 | D33: ALPHA D3 PREMIX (Alura) | F33: 12 | G33: Kg | H33: 10 | I33: =F33*H33 -> 120 | K33: 8800 | M33: =K33*L33 -> 0 | N33: =K33+M33 -> 8800 | P33: 45061 | R33: PO / NBF / 150523 / 23 | T33: Sapience Agribusiness Cons LLP
A34: 26 | B34: 45060 | D34: Hipraviar Clone-79 (Hipra) | F34: 20 | G34: Dose | H34: 2500 | I34: =F34*H34 -> 50000 | K34: 296 | L34: 0.05 | M34: =K34*L34 -> 14.8 | N34: =K34+M34 -> 310.8 | P34: 45061 | R34: PO / NBF / 150523 / 24 | T34: Tara Enterprises, Hyderabad
A35: 27 | B35: 45060 | D35: Hipraviar Clon H-120 (Hipra) | F35: 40 | G35: Dose | H35: 2500 | I35: =F35*H35 -> 100000 | K35: 550 | L35: 0.05 | M35: =K35*L35 -> 27.5 | N35: =K35+M35 -> 577.5 | P35: 45061 | R35: PO / NBF / 150523 / 24 | T35: Tara Enterprises, Hyderabad
A36: 28 | B36: 45060 | D36: Fowl Pox Live Vaccine (Venkys) | F36: 45 | G36: Dose | H36: 1000 | I36: =F36*H36 -> 45000 | K36: 125 | L36: 0.05 | M36: =K36*L36 -> 6.25 | N36: =K36+M36 -> 131.25 | P36: 45062 | R36: PO / NBF / 160523 / 25 | T36: Venkateshwara Hatcheries Ltd
A37: 29 | B37: 45060 | D37: AE KILLED VAC (Venkys) | F37: 44 | G37: Dose | H37: 1000 | I37: =F37*H37 -> 44000 | K37: 1995 | L37: 0.05 | M37: =K37*L37 -> 99.75 | N37: =K37+M37 -> 2094.75 | P37: 45062 | R37: PO / NBF / 160523 / 25 | T37: Venkateshwara Hatcheries Ltd
A38: 30 | B38: 45060 | D38: IBD KILLED VAC (Venkys) | F38: 120 | G38: Dose | H38: 400 | I38: =F38*H38 -> 48000 | K38: 896 | L38: 0.05 | M38: =K38*L38 -> 44.8 | N38: =K38+M38 -> 940.8 | P38: 45062 | R38: PO / NBF / 160523 / 25 | T38: Venkateshwara Hatcheries Ltd
A39: 31 | B39: 45060 | D39: MG KILLED VAC (Venkys) | F39: 95 | G39: Dose | H39: 1000 | I39: =F39*H39 -> 95000 | K39: 4200 | L39: 0.05 | M39: =K39*L39 -> 210 | N39: =K39+M39 -> 4410 | P39: 45062 | R39: PO / NBF / 160523 / 25 | T39: Venkateshwara Hatcheries Ltd
A40: 32 | B40: 45060 | D40: VENNEW BRO KILLED VAC (Venkys) | F40: 48 | G40: Dose | H40: 1000 | I40: =F40*H40 -> 48000 | K40: 3145 | L40: 0.05 | M40: =K40*L40 -> 157.25 | N40: =K40+M40 -> 3302.25 | P40: 45062 | R40: PO / NBF / 160523 / 25 | T40: Venkateshwara Hatcheries Ltd
A41: 33 | B41: 45060 | D41: SALMONELLA KILLED VAC | F41: 43 | G41: Dose | H41: 1000 | I41: =F41*H41 -> 43000 | K41: 2835 | L41: 0.05 | M41: =K41*L41 -> 141.75 | N41: =K41+M41 -> 2976.75 | P41: 45062 | R41: PO / NBF / 160523 / 25 | T41: Venkateshwara Hatcheries Ltd
A42: 34 | B42: 45060 | D42: VH F1C7 (FC+IC) KILLED VAC | F42: 42 | G42: Dose | H42: 1000 | I42: =F42*H42 -> 42000 | K42: 2363 | L42: 0.05 | M42: =K42*L42 -> 118.15 | N42: =K42+M42 -> 2481.15 | P42: 45062 | R42: PO / NBF / 160523 / 25 | T42: Venkateshwara Hatcheries Ltd
A43: 35 | B43: 45060 | D43: Sterile Diluent for Live Vac | F43: 50 | G43: Ml | H43: 30 | I43: =F43*H43 -> 1500 | K43: 1.75 | L43: 0.05 | M43: =K43*L43 -> 0.0875 | N43: =K43+M43 -> 1.8375 | P43: 45062 | R43: PO / NBF / 160523 / 25 | T43: Venkateshwara Hatcheries Ltd
A44: 36 | B44: 45068 | D44: TRACEMIN BB (BV Biocrop) | F44: 34 | G44: Kg | H44: 30 | I44: =F44*H44 -> 1020 | K44: 1957 | M44: =K44*L44 -> 0 | N44: =K44+M44 -> 1957 | P44: 45068 | R44: PO / NBF / 220523 / 26 | T44: B V Biocrop, Hitech Division
A45: 37 | B45: 45068 | D45: FLOXLEVO-BH (Zenex-AH) | F45: 100 | G45: Ltr | H45: 1 | I45: =F45*H45 -> 100 | K45: 965 | L45: 0.12 | M45: =K45*L45 -> 115.8 | N45: =K45+M45 -> 1080.8 | P45: 45068 | R45: PO / NBF / 220523 / 27 | T45: Crescent Marketing, Hyderabad
...

Sheet Account Details Apr23-Mar24
B3: NBF | E3: ORDER DETAILS AS PER INDENT OF NARAENDRA BREEDING FARMS | S3: Update as on 30.03.2024
B5: INDENT | D5: HITECH BREEDING FARMS | F5: D E T A I L S A B O U T I T E M | K5: D E T A I L S A B O U T O R D E R | P5: D E T A I L S A B O U T P A Y M E N T
B7: PURCHASE ORDER DATE | D7: NAME OF SUPPLIER | F7: ITEM DESCRIPTION | H7: UOM | I7: OREDR QTY | K7: PO DATE & PO NO | N7: Payable Amount | P7: GRN DATE | Q7: GRN NO | R7: CR LIMIT | S7: PAYMENT SCHEDULE | T7: DATE OF PAYMENT | U7: PAYMENT AMOUNT
P8: mm/dd/yy | T8: mm/dd/yy
A9: 1 | B9: =+'Order Details Apr23-Mar24'!P9 -> 45022 | D9: =+'Order Details Apr23-Mar24'!T9 -> APC Nutrients Limited | F9: =+'Order Details Apr23-Mar24'!D9 -> VOLAMEL (Nukamel) | H9: =+'Order Details Apr23-Mar24'!G9 -> Kg | I9: =+'Order Details Apr23-Mar24'!I9 -> 500 | K9: =+'Order Details Apr23-Mar24'!R9 -> PO / NBF / 060423 / 01 | N9: =+'Order Details Apr23-Mar24'!F9*'Order Details Apr23-Mar24'!N9 -> 285000 | Q9: 7 | S9: =P9+R9 -> 0
A10: 2 | B10: =+'Order Details Apr23-Mar24'!P10 -> 45022 | D10: =+'Order Details Apr23-Mar24'!T10 -> Das Drug Centre, Habra | F10: =+'Order Details Apr23-Mar24'!D10 -> MG BAC KILLED VAC (Zoetis) | H10: =+'Order Details Apr23-Mar24'!G10 -> Dose | I10: =+'Order Details Apr23-Mar24'!I10 -> 22000 | K10: =+'Order Details Apr23-Mar24'!R10 -> PO / NBF / 060423 / 02 | N10: =+'Order Details Apr23-Mar24'!F10*'Order Details Apr23-Mar24'!N10 -> 153615 | Q10: 45 | S10: =P10+R10 -> 0
A11: 3 | B11: =+'Order Details Apr23-Mar24'!P11 -> 45022 | D11: =+'Order Details Apr23-Mar24'!T11 -> PP & B Mart Pvt Ltd, Habra | F11: =+'Order Details Apr23-Mar24'!D11 -> MASTERSORB (EW Nutrition) | H11: =+'Order Details Apr23-Mar24'!G11 -> Kg | I11: =+'Order Details Apr23-Mar24'!I11 -> 500 | K11: =+'Order Details Apr23-Mar24'!R11 -> PO / NBF / 060423 / 03 | N11: =+'Order Details Apr23-Mar24'!F11*'Order Details Apr23-Mar24'!N11 -> 64000 | Q11: 45 | S11: =P11+R11 -> 0
A12: 4 | B12: =+'Order Details Apr23-Mar24'!P12 -> 45022 | D12: =+'Order Details Apr23-Mar24'!T12 -> Venkateshwara Hatcheries Ltd | F12: =+'Order Details Apr23-Mar24'!D12 -> ND KILLED (Visa-15) VAC | H12: =+'Order Details Apr23-Mar24'!G12 -> Dose | I12: =+'Order Details Apr23-Mar24'!I12 -> 44000 | K12: =+'Order Details Apr23-Mar24'!R12 -> PO / NBF / 060423 / 04 | N12: =+'Order Details Apr23-Mar24'!F12*'Order Details Apr23-Mar24'!N12 -> 47355 | Q12: 45 | S12: =P12+R12 -> 0
A13: 5 | B13: =+'Order Details Apr23-Mar24'!P13 -> 45024 | D13: =+'Order Details Apr23-Mar24'!T13 -> Alivira Animal Health Ltd | F13: =+'Order Details Apr23-Mar24'!D13 -> TRITYL - 62.5 (Alivira) | H13: =+'Order Details Apr23-Mar24'!G13 -> Gms | I13: =+'Order Details Apr23-Mar24'!I13 -> 12800 | K13: =+'Order Details Apr23-Mar24'!R13 -> PO / NBF / 080423 / 05 | N13: =+'Order Details Apr23-Mar24'!F13*'Order Details Apr23-Mar24'!N13 -> 306432 | Q13: 45 | S13: =P13+R13 -> 0
A14: 6 | B14: =+'Order Details Apr23-Mar24'!P14 -> 45024 | D14: =+'Order Details Apr23-Mar24'!T14 -> B V Biocrop, Hitech Division | F14: =+'Order Details Apr23-Mar24'!D14 -> BIO BUSTER PLUS (B V Biocrop) | H14: =+'Order Details Apr23-Mar24'!G14 -> Gms | I14: =+'Order Details Apr23-Mar24'!I14 -> 30000 | K14: =+'Order Details Apr23-Mar24'!R14 -> PO / NBF / 080423 / 06 | N14: =+'Order Details Apr23-Mar24'!F14*'Order Details Apr23-Mar24'!N14 -> 28674 | Q14: 45 | S14: =P14+R14 -> 0
A15: 7 | B15: =+'Order Details Apr23-Mar24'!P15 -> 45024 | D15: =+'Order Details Apr23-Mar24'!T15 -> Das Drug Centre, Habra | F15: =+'Order Details Apr23-Mar24'!D15 -> BAYROCIN (Elanco) | H15: =+'Order Details Apr23-Mar24'!G15 -> Ltr | I15: =+'Order Details Apr23-Mar24'!I15 -> 100 | K15: =+'Order Details Apr23-Mar24'!R15 -> PO / NBF / 080423 / 07 | N15: =+'Order Details Apr23-Mar24'!F15*'Order Details Apr23-Mar24'!N15 -> 65254 | Q15: 45 | S15: =P15+R15 -> 0
A16: 8 | B16: =+'Order Details Apr23-Mar24'!P16 -> 45024 | D16: =+'Order Details Apr23-Mar24'!T16 -> Das Drug Centre, Habra | F16: =+'Order Details Apr23-Mar24'!D16 -> EKTOMIN (Elanco) | H16: =+'Order Details Apr23-Mar24'!G16 -> Ltr | I16: =+'Order Details Apr23-Mar24'!I16 -> 50 | K16: =+'Order Details Apr23-Mar24'!R16 -> PO / NBF / 080423 / 07 | N16: =+'Order Details Apr23-Mar24'!F16*'Order Details Apr23-Mar24'!N16 -> 33600 | Q16: 45 | S16: =P16+R16 -> 0
A17: 9 | B17: =+'Order Details Apr23-Mar24'!P17 -> 45024 | D17: =+'Order Details Apr23-Mar24'!T17 -> Das Drug Centre, Habra | F17: =+'Order Details Apr23-Mar24'!D17 -> FAMITONE (Zenex AH) | H17: =+'Order Details Apr23-Mar24'!G17 -> Ltr | I17: =+'Order Details Apr23-Mar24'!I17 -> 60 | K17: =+'Order Details Apr23-Mar24'!R17 -> PO / NBF / 080423 / 07 | N17: =+'Order Details Apr23-Mar24'!F17*'Order Details Apr23-Mar24'!N17 -> 34800 | Q17: 45 | S17: =P17+R17 -> 0
A18: 10 | B18: =+'Order Details Apr23-Mar24'!P18 -> 45030 | D18: =+'Order Details Apr23-Mar24'!T18 -> Hester Biosciences Limited | F18: =+'Order Details Apr23-Mar24'!D18 -> INACTIVATED ND (LPAI) | H18: =+'Order Details Apr23-Mar24'!G18 -> Dose | I18: =+'Order Details Apr23-Mar24'!I18 -> 70000 | K18: =+'Order Details Apr23-Mar24'!R18 -> PO / NBF / 140423 / 08 | N18: =+'Order Details Apr23-Mar24'!F18*'Order Details Apr23-Mar24'!N18 -> 66332.28 | Q18: 45 | S18: =P18+R18 -> 0
A19: 11 | B19: =+'Order Details Apr23-Mar24'!P19 -> 45033 | D19: =+'Order Details Apr23-Mar24'!T19 -> Healers Associates, Vijayawada | F19: =+'Order Details Apr23-Mar24'!D19 -> SPERMED (Medichem Product) | H19: =+'Order Details Apr23-Mar24'!G19 -> Kg | I19: =+'Order Details Apr23-Mar24'!I19 -> 30 | K19: =+'Order Details Apr23-Mar24'!R19 -> PO / NBF / 170423 / 09 | N19: =+'Order Details Apr23-Mar24'!F19*'Order Details Apr23-Mar24'!N19 -> 105000 | Q19: 45 | S19: =P19+R19 -> 0
A20: 12 | B20: =+'Order Details Apr23-Mar24'!P20 -> 45033 | D20: =+'Order Details Apr23-Mar24'!T20 -> Huve Pharma Sea Pune Pvt Ltd | F20: =+'Order Details Apr23-Mar24'!D20 -> BIO D - 100 (Huvepharma) | H20: =+'Order Details Apr23-Mar24'!G20 -> Kg | I20: =+'Order Details Apr23-Mar24'!I20 -> 400 | K20: =+'Order Details Apr23-Mar24'!R20 -> PO / NBF / 170423 / 10 | N20: =+'Order Details Apr23-Mar24'!F20*'Order Details Apr23-Mar24'!N20 -> 640000 | Q20: 45 | S20: =P20+R20 -> 0
... A23: 15 | B23: =+'Order Details Apr23-Mar24'!P23 -> 45036 | D23: =+'Order Details Apr23-Mar24'!T23 -> Venkateshwara Hatcheries Ltd | F23: =+'Order Details Apr23-Mar24'!D23 -> ND KILLED (Visa-15) VAC | H23: =+'Order Details Apr23-Mar24'!G23 -> Dose | I23: =+'Order Details Apr23-Mar24'!I23 -> 49000 | K23: =+'Order Details Apr23-Mar24'!R23 -> PO / NBF / 200423 / 13 | N23: =+'Order Details Apr23-Mar24'!F23*'Order Details Apr23-Mar24'!N23 -> 52736.25 | Q23: 45 | S23: =P23+R23 -> 0
A24: 16 | B24: =+'Order Details Apr23-Mar24'!P24 -> 45040 | D24: =+'Order Details Apr23-Mar24'!T24 -> Stallen South Asia Pvt Ltd | F24: =+'Order Details Apr23-Mar24'!D24 -> FORLUTIN-10% (Stallen) | H24: =+'Order Details Apr23-Mar24'!G24 -> Kg | I24: =+'Order Details Apr23-Mar24'!I24 -> 200 | K24: =+'Order Details Apr23-Mar24'!R24 -> PO / NBF / 240423 / 14 | N24: =+'Order Details Apr23-Mar24'!F24*'Order Details Apr23-Mar24'!N24 -> 141000 | P24: CANCELLED | Q24: 45 | S24: =P24+R24 -> #VALUE!
A25: 17 | B25: =+'Order Details Apr23-Mar24'!P25 -> 45040 | D25: =+'Order Details Apr23-Mar24'!T25 -> Varsha Multitech, Bangallore | F25: =+'Order Details Apr23-Mar24'!D25 -> HEPATOCARE PREMIX (Varsha) | H25: =+'Order Details Apr23-Mar24'!G25 -> Kg | I25: =+'Order Details Apr23-Mar24'!I25 -> 500 | K25: =+'Order Details Apr23-Mar24'!R25 -> PO / NBF / 240423 / 15 | N25: =+'Order Details Apr23-Mar24'!F25*'Order Details Apr23-Mar24'!N25 -> 25000 | Q25: 45 | S25: =P25+R25 -> 0
A26: 18 | B26: =+'Order Details Apr23-Mar24'!P26 -> 45041 | D26: =+'Order Details Apr23-Mar24'!T26 -> Healers Associates, Vijayawada | F26: =+'Order Details Apr23-Mar24'!D26 -> TIAMU-MED (Medichem Product) | H26: =+'Order Details Apr23-Mar24'!G26 -> Kg | I26: =+'Order Details Apr23-Mar24'!I26 -> 200 | K26: =+'Order Details Apr23-Mar24'!R26 -> PO / NBF / 250423 / 16 | N26: =+'Order Details Apr23-Mar24'!F26*'Order Details Apr23-Mar24'!N26 -> 135000 | Q26: 45 | S26: =P26+R26 -> 0
A27: 19 | B27: =+'Order Details Apr23-Mar24'!P27 -> 45045 | D27: =+'Order Details Apr23-Mar24'!T27 -> Sai Kiran Medical Agencies | F27: =+'Order Details Apr23-Mar24'!D27 -> SALCOCHEK (Ayurvet) | H27: =+'Order Details Apr23-Mar24'!G27 -> Kg | I27: =+'Order Details Apr23-Mar24'!I27 -> 200 | K27: =+'Order Details Apr23-Mar24'!R27 -> PO / NBF / 290423 / 17 | N27: =+'Order Details Apr23-Mar24'!F27*'Order Details Apr23-Mar24'!N27 -> 28672 | Q27: 45 | S27: =P27+R27 -> 0
A28: 20 | B28: =+'Order Details Apr23-Mar24'!P28 -> 45050 | D28: =+'Order Details Apr23-Mar24'!T28 -> Trouw Nutrition India Pvt Ltd | F28: =+'Order Details Apr23-Mar24'!D28 -> Breeder Vitamin Premix (Custom) | H28: =+'Order Details Apr23-Mar24'!G28 -> Kg | I28: =+'Order Details Apr23-Mar24'!I28 -> 500 | K28: =+'Order Details Apr23-Mar24'!R28 -> PO / NBF / 040523 / 18 | N28: =+'Order Details Apr23-Mar24'!F28*'Order Details Apr23-Mar24'!N28 -> 292500 | Q28: 45 | S28: =P28+R28 -> 0
A29: 21 | B29: =+'Order Details Apr23-Mar24'!P29 -> 45054 | D29: =+'Order Details Apr23-Mar24'!T29 -> Tara Enterprises, Hyderabad | F29: =+'Order Details Apr23-Mar24'!D29 -> Hipraviar Clon H-120 (Hipra) | H29: =+'Order Details Apr23-Mar24'!G29 -> Dose | I29: =+'Order Details Apr23-Mar24'!I29 -> 250000 | K29: =+'Order Details Apr23-Mar24'!R29 -> PO / NBF / 080523 / 19 | N29: =+'Order Details Apr23-Mar24'!F29*'Order Details Apr23-Mar24'!N29 -> 57750 | Q29: 45 | S29: =P29+R29 -> 0
A30: 22 | B30: =+'Order Details Apr23-Mar24'!P30 -> 45057 | D30: =+'Order Details Apr23-Mar24'!T30 -> Kemin Industries South Asia | F30: =+'Order Details Apr23-Mar24'!D30 -> CLOSTAT-365 / 12 (Kemin Indus) | H30: =+'Order Details Apr23-Mar24'!G30 -> Kg | I30: =+'Order Details Apr23-Mar24'!I30 -> 200 | K30: =+'Order Details Apr23-Mar24'!R30 -> PO / NBF / 110523 / 20 | N30: =+'Order Details Apr23-Mar24'!F30*'Order Details Apr23-Mar24'!N30 -> 100000 | Q30: 45 | S30: =P30+R30 -> 0
A31: 23 | B31: =+'Order Details Apr23-Mar24'!P31 -> 45061 | D31: =+'Order Details Apr23-Mar24'!T31 -> Alivira Animal Health Ltd | F31: =+'Order Details Apr23-Mar24'!D31 -> CITRINAL (Alivira) | H31: =+'Order Details Apr23-Mar24'!G31 -> Kg | I31: =+'Order Details Apr23-Mar24'!I31 -> 500 | K31: =+'Order Details Apr23-Mar24'!R31 -> PO / NBF / 150523 / 21 | N31: =+'Order Details Apr23-Mar24'!F31*'Order Details Apr23-Mar24'!N31 -> 75000 | Q31: 45 | S31: =P31+R31 -> 0
A32: 24 | B32: =+'Order Details Apr23-Mar24'!P32 -> 45060 | D32: =+'Order Details Apr23-Mar24'!T32 -> Hester Biosciences Limited | F32: =+'Order Details Apr23-Mar24'!D32 -> ILT(GI- 10000) Live Vaccine | H32: =+'Order Details Apr23-Mar24'!G32 -> Dose | I32: =+'Order Details Apr23-Mar24'!I32 -> 42000 | K32: =+'Order Details Apr23-Mar24'!R32 -> PO / NBF / 150523 / 22 | N32: =+'Order Details Apr23-Mar24'!F32*'Order Details Apr23-Mar24'!N32 -> 66150 | Q32: 45 | S32: =P32+R32 -> 0
A33: 25 | B33: =+'Order Details Apr23-Mar24'!P33 -> 45061 | D33: =+'Order Details Apr23-Mar24'!T33 -> Sapience Agribusiness Cons LLP | F33: =+'Order Details Apr23-Mar24'!D33 -> ALPHA D3 PREMIX (Alura) | H33: =+'Order Details Apr23-Mar24'!G33 -> Kg | I33: =+'Order Details Apr23-Mar24'!I33 -> 120 | K33: =+'Order Details Apr23-Mar24'!R33 -> PO / NBF / 150523 / 23 | N33: =+'Order Details Apr23-Mar24'!F33*'Order Details Apr23-Mar24'!N33 -> 105600 | Q33: 45 | S33: =P33+R33 -> 0
A34: 26 | B34: =+'Order Details Apr23-Mar24'!P34 -> 45061 | D34: =+'Order Details Apr23-Mar24'!T34 -> Tara Enterprises, Hyderabad | F34: =+'Order Details Apr23-Mar24'!D34 -> Hipraviar Clone-79 (Hipra) | H34: =+'Order Details Apr23-Mar24'!G34 -> Dose | I34: =+'Order Details Apr23-Mar24'!I34 -> 50000 | K34: =+'Order Details Apr23-Mar24'!R34 -> PO / NBF / 150523 / 24 | N34: =+'Order Details Apr23-Mar24'!F34*'Order Details Apr23-Mar24'!N34 -> 6216 | Q34: 45 | S34: =P34+R34 -> 0
A35: 27 | B35: =+'Order Details Apr23-Mar24'!P35 -> 45061 | D35: =+'Order Details Apr23-Mar24'!T35 -> Tara Enterprises, Hyderabad | F35: =+'Order Details Apr23-Mar24'!D35 -> Hipraviar Clon H-120 (Hipra) | H35: =+'Order Details Apr23-Mar24'!G35 -> Dose | I35: =+'Order Details Apr23-Mar24'!I35 -> 100000 | K35: =+'Order Details Apr23-Mar24'!R35 -> PO / NBF / 150523 / 24 | N35: =+'Order Details Apr23-Mar24'!F35*'Order Details Apr23-Mar24'!N35 -> 23100 | Q35: 45 | S35: =P35+R35 -> 0
A36: 28 | B36: =+'Order Details Apr23-Mar24'!P36 -> 45062 | D36: =+'Order Details Apr23-Mar24'!T36 -> Venkateshwara Hatcheries Ltd | F36: =+'Order Details Apr23-Mar24'!D36 -> Fowl Pox Live Vaccine (Venkys) | H36: =+'Order Details Apr23-Mar24'!G36 -> Dose | I36: =+'Order Details Apr23-Mar24'!I36 -> 45000 | K36: =+'Order Details Apr23-Mar24'!R36 -> PO / NBF / 160523 / 25 | N36: =+'Order Details Apr23-Mar24'!F36*'Order Details Apr23-Mar24'!N36 -> 5906.25 | Q36: 45 | S36: =P36+R36 -> 0
... A133: 125 | B133: =+'Order Details Apr23-Mar24'!P133 -> 45194 | D133: =+'Order Details Apr23-Mar24'!T133 -> Das Drug Centre, Habra | F133: =+'Order Details Apr23-Mar24'!D133 -> HIM-C (Himalaya) | H133: =+'Order Details Apr23-Mar24'!G133 -> Kg | I133: =+'Order Details Apr23-Mar24'!I133 -> 500 | K133: =+'Order Details Apr23-Mar24'!R133 -> PO / NBF / 250923 / 90 | N133: =+'Order Details Apr23-Mar24'!F133*'Order Details Apr23-Mar24'!N133 -> 67500 | Q133: 45 | S133: =P133+R133 -> 0
A134: 126 | B134: =+'Order Details Apr23-Mar24'!P134 -> 45198 | D134: =+'Order Details Apr23-Mar24'!T134 -> Stallen South Asia Pvt Ltd | F134: =+'Order Details Apr23-Mar24'!D134 -> FORLUTIN 10% (Stallen) | H134: =+'Order Details Apr23-Mar24'!G134 -> Kg | I134: =+'Order Details Apr23-Mar24'!I134 -> 300 | K134: =+'Order Details Apr23-Mar24'!R134 -> PO / NBF / 290923 / 91 | N134: =+'Order Details Apr23-Mar24'!F134*'Order Details Apr23-Mar24'!N134 -> 211500 | P134: CANCELLED | Q134: 45 | S134: =P134+R134 -> #VALUE!
A135: 127 | B135: =+'Order Details Apr23-Mar24'!P135 -> 45198 | D135: =+'Order Details Apr23-Mar24'!T135 -> Varsha Multitech, Bangallore | F135: =+'Order Details Apr23-Mar24'!D135 -> HEPATOCARE PREMIX (Varsha) | H135: =+'Order Details Apr23-Mar24'!G135 -> Kg | I135: =+'Order Details Apr23-Mar24'!I135 -> 500 | K135: =+'Order Details Apr23-Mar24'!R135 -> PO / NBF / 290923 / 92 | N135: =+'Order Details Apr23-Mar24'!F135*'Order Details Apr23-Mar24'!N135 -> 25000 | Q135: 45 | S135: =P135+R135 -> 0
A136: 128 | B136: =+'Order Details Apr23-Mar24'!P136 -> 45198 | D136: =+'Order Details Apr23-Mar24'!T136 -> Ves Spa, Barasat, West Bengal | F136: =+'Order Details Apr23-Mar24'!D136 -> VES CHOL 60% (Vesper) | H136: =+'Order Details Apr23-Mar24'!G136 -> Kg | I136: =+'Order Details Apr23-Mar24'!I136 -> 1000 | K136: =+'Order Details Apr23-Mar24'!R136 -> PO / NBF / 290923 / 93 | N136: =+'Order Details Apr23-Mar24'!F136*'Order Details Apr23-Mar24'!N136 -> 90000 | Q136: 45 | S136: =P136+R136 -> 0
A137: 129 | B137: =+'Order Details Apr23-Mar24'!P137 -> 45198 | D137: =+'Order Details Apr23-Mar24'!T137 -> Zeus Biotech Pvt Ltd, Mysore | F137: =+'Order Details Apr23-Mar24'!D137 -> SELCON FORTE (Zeus Biotech) | H137: =+'Order Details Apr23-Mar24'!G137 -> Kg | I137: =+'Order Details Apr23-Mar24'!I137 -> 150 | K137: =+'Order Details Apr23-Mar24'!R137 -> PO / NBF / 290923 / 94 | N137: =+'Order Details Apr23-Mar24'!F137*'Order Details Apr23-Mar24'!N137 -> 60000 | Q137: 45 | S137: =P137+R137 -> 0
A138: 130 | B138: =+'Order Details Apr23-Mar24'!P138 -> 45198 | D138: =+'Order Details Apr23-Mar24'!T138 -> Healers Associates, Vijayawada | F138: =+'Order Details Apr23-Mar24'!D138 -> TIAMU-MED (Medichem Product) | H138: =+'Order Details Apr23-Mar24'!G138 -> Kg | I138: =+'Order Details Apr23-Mar24'!I138 -> 300 | K138: =+'Order Details Apr23-Mar24'!R138 -> PO / NBF / 290923 / 95 | N138: =+'Order Details Apr23-Mar24'!F138*'Order Details Apr23-Mar24'!N138 -> 202500 | Q138: 45 | S138: =P138+R138 -> 0
A139: 131 | B139: =+'Order Details Apr23-Mar24'!P139 -> 45204 | D139: =+'Order Details Apr23-Mar24'!T139 -> Venkys India Ltd, AHP Division | F139: =+'Order Details Apr23-Mar24'!D139 -> TRACEMIN BB (BV Biocrop) | H139: =+'Order Details Apr23-Mar24'!G139 -> Kg | I139: =+'Order Details Apr23-Mar24'!I139 -> 1020 | K139: =+'Order Details Apr23-Mar24'!R139 -> PO / NBF / 051023 / 96 | N139: =+'Order Details Apr23-Mar24'!F139*'Order Details Apr23-Mar24'!N139 -> 66538 | Q139: 45 | S139: =P139+R139 -> 0
A140: 132 | B140: =+'Order Details Apr23-Mar24'!P140 -> 45204 | D140: =+'Order Details Apr23-Mar24'!T140 -> Das Drug Centre, Habra | F140: =+'Order Details Apr23-Mar24'!D140 -> LIV-52 PROTEC (Himalaya) | H140: =+'Order Details Apr23-Mar24'!G140 -> Ltr | I140: =+'Order Details Apr23-Mar24'!I140 -> 100 | K140: =+'Order Details Apr23-Mar24'!R140 -> PO / NBF / 051023 / 97 | N140: =+'Order Details Apr23-Mar24'!F140*'Order Details Apr23-Mar24'!N140 -> 9900 | Q140: 45 | S140: =P140+R140 -> 0
A141: 133 | B141: =+'Order Details Apr23-Mar24'!P141 -> 45204 | D141: =+'Order Details Apr23-Mar24'!T141 -> Das Drug Centre, Habra | F141: =+'Order Details Apr23-Mar24'!D141 -> TYLOMAX Injection (Intas) | H141: =+'Order Details Apr23-Mar24'!G141 -> Ml | I141: =+'Order Details Apr23-Mar24'!I141 -> 10000 | K141: =+'Order Details Apr23-Mar24'!R141 -> PO / NBF / 051023 / 97 | N141: =+'Order Details Apr23-Mar24'!F141*'Order Details Apr23-Mar24'!N141 -> 25200 | Q141: 45 | S141: =P141+R141 -> 0
A142: 134 | B142: =+'Order Details Apr23-Mar24'!P142 -> 45204 | D142: =+'Order Details Apr23-Mar24'!T142 -> Das Drug Centre, Habra | F142: =+'Order Details Apr23-Mar24'!D142 -> Urimin Injection (Virbac) | H142: =+'Order Details Apr23-Mar24'!G142 -> Ml | I142: =+'Order Details Apr23-Mar24'!I142 -> 10000 | K142: =+'Order Details Apr23-Mar24'!R142 -> PO / NBF / 051023 / 97 | N142: =+'Order Details Apr23-Mar24'!F142*'Order Details Apr23-Mar24'!N142 -> 35754.88 | Q142: 45 | S142: =P142+R142 -> 0
...

Sheet Order Details Apr24 - Mar25
B3: NBF | E3: ORDER DETAILS AS PER INDENT OF NARAENDRA BREEDING FARMS | S3: Update as on 29.03.2025
B5: INDENT | D5: NARAENDRA BREEDING FARMS | F5: D E T A I L S A B O U T I T E M | K5: D E T A I L S A B O U T P R I C E | P5: D E T A I L S A B O U T P U R C H A S E O R D E R
B7: DATE OF INDENT | D7: NAME OF ITEM | F7: REQUIRE QTY | G7: UOM | H7: PACK SIZE | I7: OREDR QTY | K7: PRICE | L7: GST % | M7: GST Crgs | N7: NET PRICE | P7: PO RAISED ON | R7: PO DATE / NO | T7: NAME OF SUPPLIER
A9: 1 | B9: 45390 | D9: AQUAMAX (BV Biocrop) | F9: 20 | G9: Ltr | H9: 50 | I9: =F9*H9 -> 1000 | K9: 457 | L9: 0.18 | M9: =K9*L9 -> 82.26 | N9: =K9+M9 -> 539.26 | P9: 45390 | R9: PO / NBF / 080424 / 01 | T9: B V Biocrop, Hitech Division
A10: 2 | B10: 45390 | D10: SAFEGARD (BV Biocrop) | F10: 20 | G10: Ltr | H10: 5 | I10: =F10*H10 -> 100 | K10: 1138 | L10: 0.18 | M10: =K10*L10 -> 204.84 | N10: =K10+M10 -> 1342.84 | P10: 45390 | R10: PO / NBF / 080424 / 01 | T10: B V Biocrop, Hitech Division
A11: 3 | B11: 45390 | D11: ELECTROCARE PLUS (Cargill) | F11: 200 | G11: Kg | H11: 1 | I11: =F11*H11 -> 200 | K11: 189 | M11: =K11*L11 -> 0 | N11: =K11+M11 -> 189 | P11: 45390 | R11: PO / NBF / 080424 / 02 | T11: Das Drug Centre Pvt Ltd, Habra
A12: 4 | B12: 45390 | D12: E CARE SE (Cargill) | F12: 300 | G12: Gms | H12: 200 | I12: =F12*H12 -> 60000 | K12: 190 | M12: =K12*L12 -> 0 | N12: =K12+M12 -> 190 | P12: 45390 | R12: PO / NBF / 080424 / 02 | T12: Das Drug Centre Pvt Ltd, Habra
A13: 5 | B13: 45390 | D13: FAMITONE (Zenex-AH) | F13: 48 | G13: Ltr | H13: 1 | I13: =F13*H13 -> 48 | K13: 580 | M13: =K13*L13 -> 0 | N13: =K13+M13 -> 580 | P13: 45390 | R13: PO / NBF / 080424 / 02 | T13: Das Drug Centre Pvt Ltd, Habra
A14: 6 | B14: 45390 | D14: HERBAL-C Liquid (Indian Herbs) | F14: 40 | G14: Ltr | H14: 5 | I14: =F14*H14 -> 200 | K14: 730 | M14: =K14*L14 -> 0 | N14: =K14+M14 -> 730 | P14: 45390 | R14: PO / NBF / 080424 / 02 | T14: Das Drug Centre Pvt Ltd, Habra
A15: 7 | B15: 45380 | D15: ROVIMIX BREEDER (DSM) | F15: 40 | G15: Kg | H15: 25 | I15: =F15*H15 -> 1000 | K15: 12175 | M15: =K15*L15 -> 0 | N15: =K15+M15 -> 12175 | P15: 45390 | R15: PO / NBF / 080424 / 03 | T15: Jeco Agrovet Pvt Ltd Kolkata
A16: 8 | B16: 45390 | D16: SELVIT-E (AHP Division) | F16: 210 | G16: Gms | H16: 200 | I16: =F16*H16 -> 42000 | K16: 200 | M16: =K16*L16 -> 0 | N16: =K16+M16 -> 200 | P16: 45390 | R16: PO / NBF / 080424 / 04 | T16: Venkys India Ltd (AHP Division)
A17: 9 | B17: 45394 | D17: BIOPLEX PRIME (Alltech) | F17: 20 | G17: Kg | H17: 25 | I17: =F17*H17 -> 500 | K17: 6700 | M17: =K17*L17 -> 0 | N17: =K17+M17 -> 6700 | P17: 45394 | R17: PO / NBF / 120424 / 05 | T17: Alltech Biotechnology Pvt Ltd
A18: 10 | B18: 45394 | D18: PHYTOCEE (Natural Remedies) | F18: 40 | G18: Kg | H18: 25 | I18: =F18*H18 -> 1000 | K18: 4850 | M18: =K18*L18 -> 0 | N18: =K18+M18 -> 4850 | P18: 45394 | R18: PO / NBF / 120424 / 06 | T18: Das Drug Centre Pvt Ltd, Habra
A19: 11 | B19: 45394 | D19: HEPATOCARE PREMIX (Varsha) | F19: 40 | G19: Kg | H19: 25 | I19: =F19*H19 -> 1000 | K19: 1250 | M19: =K19*L19 -> 0 | N19: =K19+M19 -> 1250 | P19: 45394 | R19: PO / NBF / 120424 / 07 | T19: Varsha Multitech, Bangallore
A20: 12 | B20: 45399 | D20: TRACEMIN BB (BV Biocrop) | F20: 34 | G20: Kg | H20: 30 | I20: =F20*H20 -> 1020 | K20: 1957 | M20: =K20*L20 -> 0 | N20: =K20+M20 -> 1957 | P20: 45399 | R20: PO / NBF / 120424 / 08 | T20: B V Biocrop, Hitech Division
A21: 13 | B21: 45399 | D21: KEMZYME-XPF (Kemin Indus.) | F21: 10 | G21: Kg | H21: 25 | I21: =F21*H21 -> 250 | K21: 6050 | M21: =K21*L21 -> 0 | N21: =K21+M21 -> 6050 | P21: 45399 | R21: PO / NBF / 170424 / 09 | T21: Kemin Industries South Asia
A22: 14 | B22: 45399 | D22: ALKAKARB (Tata Chemicals) | F22: 40 | G22: Kg | H22: 50 | I22: =F22*H22 -> 2000 | K22: 1949.15 | L22: 0.18 | M22: =K22*L22 -> 350.847 | N22: =K22+M22 -> 2299.997 | P22: 45399 | R22: PO / NBF / 170424 / 10 | T22: Sneha Farms Pvt Ltd Hyderabad
A23: 15 | B23: 45399 | D23: ROVIMIX-E 50 (DSM) | F23: 8 | G23: Kg | H23: 25 | I23: =F23*H23 -> 200 | K23: 21500 | M23: =K23*L23 -> 0 | N23: =K23+M23 -> 21500 | P23: 45400 | R23: PO / NBF / 180424 / 11 | T23: Jeco Agrovet Pvt Ltd Kolkata
A24: 16 | B24: 45411 | D24: ELECTROCARE PLUS (Cargill) | F24: 300 | G24: Kg | H24: 1 | I24: =F24*H24 -> 300 | K24: 189 | M24: =K24*L24 -> 0 | N24: =K24+M24 -> 189 | P24: 45411 | R24: PO / NBF / 300424 / 12 | T24: Das Drug Centre Pvt Ltd, Habra
A25: 17 | B25: 45411 | D25: E CARE SE (Cargill) | F25: 300 | G25: Gms | H25: 200 | I25: =F25*H25 -> 60000 | K25: 190 | M25: =K25*L25 -> 0 | N25: =K25+M25 -> 190 | P25: 45411 | R25: PO / NBF / 300424 / 12 | T25: Das Drug Centre Pvt Ltd, Habra
A26: 18 | B26: 45411 | D26: ENROCIN-10% (Zoetis) | F26: 20 | G26: Ltr | H26: 5 | I26: =F26*H26 -> 100 | K26: 2587 | L26: 0.12 | M26: =K26*L26 -> 310.44 | N26: =K26+M26 -> 2897.44 | P26: 45411 | R26: PO / NBF / 300424 / 12 | T26: Das Drug Centre Pvt Ltd, Habra
A27: 19 | B27: 45411 | D27: HERBAL-C Liquid (Indian Herbs) | F27: 120 | G27: Ltr | H27: 5 | I27: =F27*H27 -> 600 | K27: 730 | M27: =K27*L27 -> 0 | N27: =K27+M27 -> 730 | P27: 45411 | R27: PO / NBF / 300424 / 12 | T27: Das Drug Centre Pvt Ltd, Habra
A28: 20 | B28: 45411 | D28: HIMFLORA (Himalaya) | F28: 60 | G28: Kg | H28: 5 | I28: =F28*H28 -> 300 | K28: 2875 | M28: =K28*L28 -> 0 | N28: =K28+M28 -> 2875 | P28: 45411 | R28: PO / NBF / 300424 / 12 | T28: Das Drug Centre Pvt Ltd, Habra
A29: 21 | B29: 45411 | D29: Oxytetracycline-LA Injection (Zenex) | F29: 200 | G29: Ml | H29: 50 | I29: =F29*H29 -> 10000 | K29: 116 | L29: 0.12 | M29: =K29*L29 -> 13.92 | N29: =K29+M29 -> 129.92 | P29: 45411 | R29: PO / NBF / 300424 / 12 | T29: Das Drug Centre Pvt Ltd, Habra
A30: 22 | B30: 45411 | D30: TAMIK Injection (TTK) | F30: 50 | G30: Ml | H30: 100 | I30: =F30*H30 -> 5000 | K30: 733 | L30: 0.12 | M30: =K30*L30 -> 87.96 | N30: =K30+M30 -> 820.96 | P30: 45411 | R30: PO / NBF / 300424 / 12 | T30: Das Drug Centre Pvt Ltd, Habra
A31: 23 | B31: 45411 | D31: TYLOMAX Injection (Intas) | F31: 50 | G31: Ml | H31: 100 | I31: =F31*H31 -> 5000 | K31: 225 | L31: 0.12 | M31: =K31*L31 -> 27 | N31: =K31+M31 -> 252 | P31: 45411 | R31: PO / NBF / 300424 / 12 | T31: Das Drug Centre Pvt Ltd, Habra
A32: 24 | B32: 45411 | D32: URIMIN Injection (Virbac) | F32: 50 | G32: Ml | H32: 100 | I32: =F32*H32 -> 5000 | K32: 319.24 | L32: 0.12 | M32: =K32*L32 -> 38.3088 | N32: =K32+M32 -> 357.5488 | P32: 45411 | R32: PO / NBF / 300424 / 12 | T32: Das Drug Centre Pvt Ltd, Habra
